Exception in thread Thread-1 (_handle_workers):
Traceback (most recent call last):
  File "/usr/lib/python3.10/threading.py", line 1009, in _bootstrap_inner
    self.run()
  File "/usr/lib/python3.10/threading.py", line 946, in run
    self._target(*self._args, **self._kwargs)
  File "/usr/lib/python3.10/multiprocessing/pool.py", line 513, in _handle_workers
    cls._maintain_pool(ctx, Process, processes, pool, inqueue,
  File "/usr/lib/python3.10/multiprocessing/pool.py", line 337, in _maintain_pool
    Pool._repopulate_pool_static(ctx, Process, processes, pool,
  File "/usr/lib/python3.10/multiprocessing/pool.py", line 326, in _repopulate_pool_static
    w.start()
  File "/usr/lib/python3.10/multiprocessing/process.py", line 121, in start
    self._popen = self._Popen(self)
  File "/usr/lib/python3.10/multiprocessing/context.py", line 277, in _Popen
    return Popen(process_obj)
  File "/usr/lib/python3.10/multiprocessing/popen_fork.py", line 19, in __init__
    self._launch(process_obj)
  File "/usr/lib/python3.10/multiprocessing/popen_fork.py", line 66, in _launch
    self.pid = os.fork()
BlockingIOError: [Errno 11] Resource temporarily unavailable
